Workbook

Sheet Times Comparison
A2: EUCLIDEAN AND BINARY GCD PERFORMANCE
A4: Time in seconds. Lower values indicate faster execution.
A5: Different input pairs are used for each algorithm. Results are compared by group.
A7: Average time (seconds)
A8: Data group | B8: Euclidean | C8: Binary GCD
A9: Random pairs | B9: ='Euclidean times'!B15 -> 2.04e-08 | C9: ='Binary GCD times'!B15 -> 4.62e-08
A10: Coprime pairs | B10: ='Euclidean times'!B35 -> 2.06e-08 | C10: ='Binary GCD times'!B35 -> 4.67e-08
A11: Power of two times a common factor | B11: ='Euclidean times'!B55 -> 2.5e-09 | C11: ='Binary GCD times'!B55 -> 2.3e-09
A22: Max time (seconds)
A23: Data group | B23: Euclidean | C23: Binary GCD
A24: Random pairs | B24: ='Euclidean times'!B16 -> 3.1e-08 | C24: ='Binary GCD times'!B16 -> 5.3e-08
A25: Coprime pairs | B25: ='Euclidean times'!B36 -> 3.5e-08 | C25: ='Binary GCD times'!B36 -> 5.3e-08
A26: Power of two times a common factor | B26: ='Euclidean times'!B56 -> 3e-09 | C26: ='Binary GCD times'!B56 -> 4e-09
A37: Min time (seconds)
A38: Data group | B38: Euclidean | C38: Binary GCD
A39: Random pairs | B39: ='Euclidean times'!B17 -> 1.3e-08 | C39: ='Binary GCD times'!B17 -> 3.6e-08
A40: Coprime pairs | B40: ='Euclidean times'!B37 -> 1.2e-08 | C40: ='Binary GCD times'!B37 -> 3.8e-08
A41: Power of two times a common factor | B41: ='Euclidean times'!B57 -> 1e-09 | C41: ='Binary GCD times'!B57 -> 1e-09

Sheet Step Comparison
A2: EUCLIDEAN AND BINARY GCD STEP COMPARISON
A4: Number of steps per GCD calculation. Lower values indicate fewer steps.
A5: Different input pairs are used for each algorithm. Results are compared by group.
A7: Average steps
A8: Data group | B8: Euclidean | C8: Binary GCD
A9: Random pairs | B9: ='Euclidean Steps'!B15 -> 10.5 | C9: ='Binary GCD Steps'!B15 -> 40.1
A10: Coprime pairs | B10: ='Euclidean Steps'!B35 -> 10.5 | C10: ='Binary GCD Steps'!B35 -> 38
A11: Power of two times a common factor | B11: ='Euclidean Steps'!B55 -> 1.6 | C11: ='Binary GCD Steps'!B55 -> 2.9
A22: Max steps
A23: Data group | B23: Euclidean | C23: Binary GCD
A24: Random pairs | B24: ='Euclidean Steps'!B16 -> 14 | C24: ='Binary GCD Steps'!B16 -> 43
A25: Coprime pairs | B25: ='Euclidean Steps'!B36 -> 15 | C25: ='Binary GCD Steps'!B36 -> 41
A26: Power of two times a common factor | B26: ='Euclidean Steps'!B56 -> 2 | C26: ='Binary GCD Steps'!B56 -> 5
A37: Min steps
A38: Data group | B38: Euclidean | C38: Binary GCD
A39: Random pairs | B39: ='Euclidean Steps'!B17 -> 8 | C39: ='Binary GCD Steps'!B17 -> 35
A40: Coprime pairs | B40: ='Euclidean Steps'!B37 -> 7 | C40: ='Binary GCD Steps'!B37 -> 32
A41: Power of two times a common factor | B41: ='Euclidean Steps'!B57 -> 1 | C41: ='Binary GCD Steps'!B57 -> 1

Sheet Euclidean times
A1: EUCLIDEAN
A3: Random pairs
A4: Pair (a, b) | B4: Time (seconds)
A5: (15784, 40279) | B5: 2.2e-08
A6: (32453, 40116) | B6: 1.7e-08
A7: (28974, 18973) | B7: 3.1e-08
A8: (22699, 19360) | B8: 2e-08
A9: (38613, 35119) | B9: 1.3e-08
A10: (13734, 26466) | B10: 1.9e-08
A11: (10166, 13646) | B11: 1.9e-08
A12: (29505, 19944) | B12: 1.6e-08
A13: (26209, 12763) | B13: 1.6e-08
A14: (42537, 17596) | B14: 3.1e-08
A15: Average time | B15: =AVERAGE(B5:B14) -> 2.04e-08
A16: Max time | B16: =MAX(B5:B14) -> 3.1e-08
A17: Min time | B17: =MIN(B5:B14) -> 1.3e-08
A23: Coprime pairs
A24: Pair (a, b) | B24: Time (seconds)
A25: (14207, 28910) | B25: 1.6e-08
A26: (28086, 40867) | B26: 1.9e-08
A27: (39433, 28575) | B27: 2.6e-08
A28: (18449, 40269) | B28: 2.2e-08
A29: (16375, 25627) | B29: 2.1e-08
A30: (31143, 38345) | B30: 2.2e-08
A31: (38375, 23778) | B31: 3.5e-08
A32: (26635, 26358) | B32: 1.2e-08
A33: (23597, 18110) | B33: 2.1e-08
A34: (36754, 28591) | B34: 1.2e-08
A35: Average time | B35: =AVERAGE(B25:B34) -> 2.06e-08
A36: Max time | B36: =MAX(B25:B34) -> 3.5e-08
A37: Min time | B37: =MIN(B25:B34) -> 1.2e-08
A43: Power of two times a common factor
A44: Pair (a, b) | B44: Time (seconds)
A45: (61348, 30674) | B45: 2e-09
A46: (17372, 69488) | B46: 3e-09
A47: (19815, 19815) | B47: 1e-09
A48: (10939, 10939) | B48: 2e-09
A49: (10991, 43964) | B49: 3e-09
A50: (11858, 23716) | B50: 3e-09
A51: (10969, 21938) | B51: 3e-09
...

Sheet Euclidean Steps
A1: EUCLIDEAN STEPS
A3: Random pairs
A4: Pair (a, b) | B4: Steps
A5: (15784, 40279) | B5: 11
A6: (32453, 40116) | B6: 10
A7: (28974, 18973) | B7: 14
A8: (22699, 19360) | B8: 10
A9: (38613, 35119) | B9: 8
A10: (13734, 26466) | B10: 10
A11: (10166, 13646) | B11: 10
A12: (29505, 19944) | B12: 9
A13: (26209, 12763) | B13: 9
A14: (42537, 17596) | B14: 14
A15: Average steps | B15: =AVERAGE(B5:B14) -> 10.5
A16: Max steps | B16: =MAX(B5:B14) -> 14
A17: Min steps | B17: =MIN(B5:B14) -> 8
A23: Coprime pairs
A24: Pair (a, b) | B24: Steps
A25: (14207, 28910) | B25: 9
A26: (28086, 40867) | B26: 10
A27: (39433, 28575) | B27: 13
A28: (18449, 40269) | B28: 11
A29: (16375, 25627) | B29: 11
A30: (31143, 38345) | B30: 11
A31: (38375, 23778) | B31: 15
A32: (26635, 26358) | B32: 7
A33: (23597, 18110) | B33: 11
A34: (36754, 28591) | B34: 7
A35: Average steps | B35: =AVERAGE(B25:B34) -> 10.5
A36: Max steps | B36: =MAX(B25:B34) -> 15
A37: Min steps | B37: =MIN(B25:B34) -> 7
A43: Power of two times a common factor
A44: Pair (a, b) | B44: Steps
A45: (61348, 30674) | B45: 1
A46: (17372, 69488) | B46: 2
A47: (19815, 19815) | B47: 1
A48: (10939, 10939) | B48: 1
A49: (10991, 43964) | B49: 2
A50: (11858, 23716) | B50: 2
A51: (10969, 21938) | B51: 2
...

Sheet Binary GCD times
A1: BINARY GCD
A3: Random pairs
A4: Pair (a, b) | B4: Time (seconds)
A5: (35873, 40676) | B5: 5.3e-08
A6: (35003, 21126) | B6: 4.2e-08
A7: (22050, 33672) | B7: 4.6e-08
A8: (33051, 11200) | B8: 4.9e-08
A9: (25505, 28348) | B9: 4.7e-08
A10: (26275, 24312) | B10: 4.6e-08
A11: (37578, 10772) | B11: 4.4e-08
A12: (28779, 19318) | B12: 4.9e-08
A13: (30738, 41273) | B13: 5e-08
A14: (41026, 23900) | B14: 3.6e-08
A15: Average time | B15: =AVERAGE(B5:B14) -> 4.62e-08
A16: Max time | B16: =MAX(B5:B14) -> 5.3e-08
A17: Min time | B17: =MIN(B5:B14) -> 3.6e-08
A23: Coprime pairs
A24: Pair (a, b) | B24: Time (seconds)
A25: (40946, 34267) | B25: 4.6e-08
A26: (31351, 24523) | B26: 5.2e-08
A27: (33733, 33702) | B27: 4.2e-08
A28: (18825, 19579) | B28: 4e-08
A29: (38471, 36775) | B29: 5.1e-08
A30: (29482, 40423) | B30: 5.2e-08
A31: (26680, 17143) | B31: 3.8e-08
A32: (35417, 16262) | B32: 5.3e-08
A33: (34676, 40187) | B33: 5.2e-08
A34: (11588, 16841) | B34: 4.1e-08
A35: Average time | B35: =AVERAGE(B25:B34) -> 4.67e-08
A36: Max time | B36: =MAX(B25:B34) -> 5.3e-08
A37: Min time | B37: =MIN(B25:B34) -> 3.8e-08
A43: Power of two times a common factor
A44: Pair (a, b) | B44: Time (seconds)
A45: (22184, 22184) | B45: 3e-09
A46: (38152, 38152) | B46: 2e-09
A47: (69756, 69756) | B47: 3e-09
A48: (36226, 36226) | B48: 1e-09
A49: (16837, 16837) | B49: 2e-09
A50: (21166, 42332) | B50: 2e-09
A51: (16058, 16058) | B51: 2e-09
...

Sheet Binary GCD Steps
A1: BINARY GCD STEPS
A3: Random pairs
A4: Pair (a, b) | B4: Steps
A5: (35873, 40676) | B5: 43
A6: (35003, 21126) | B6: 43
A7: (22050, 33672) | B7: 35
A8: (33051, 11200) | B8: 39
A9: (25505, 28348) | B9: 39
A10: (26275, 24312) | B10: 43
A11: (37578, 10772) | B11: 38
A12: (28779, 19318) | B12: 40
A13: (30738, 41273) | B13: 41
A14: (41026, 23900) | B14: 40
A15: Average steps | B15: =AVERAGE(B5:B14) -> 40.1
A16: Max steps | B16: =MAX(B5:B14) -> 43
A17: Min steps | B17: =MIN(B5:B14) -> 35
A23: Coprime pairs
A24: Pair (a, b) | B24: Steps
A25: (40946, 34267) | B25: 37
A26: (31351, 24523) | B26: 41
A27: (33733, 33702) | B27: 39
A28: (18825, 19579) | B28: 34
A29: (38471, 36775) | B29: 39
A30: (29482, 40423) | B30: 40
A31: (26680, 17143) | B31: 36
A32: (35417, 16262) | B32: 41
A33: (34676, 40187) | B33: 41
A34: (11588, 16841) | B34: 32
A35: Average steps | B35: =AVERAGE(B25:B34) -> 38
A36: Max steps | B36: =MAX(B25:B34) -> 41
A37: Min steps | B37: =MIN(B25:B34) -> 32
A43: Power of two times a common factor
A44: Pair (a, b) | B44: Steps
A45: (22184, 22184) | B45: 4
A46: (38152, 38152) | B46: 4
A47: (69756, 69756) | B47: 3
A48: (36226, 36226) | B48: 2
A49: (16837, 16837) | B49: 1
A50: (21166, 42332) | B50: 3
A51: (16058, 16058) | B51: 2
...
